Workbook

Sheet Partner
A1: Partner_ID | B1: Is_Customer | C1: Is_Supplier
A2: P0001 | B2: 1 | C2: 0
A3: P0002 | B3: 1 | C3: 0
A4: P0003 | B4: 1 | C4: 0
A5: P0004 | B5: 1 | C5: 0
A6: P0005 | B6: 1 | C6: 0
A7: P0006 | B7: 1 | C7: 0
A8: P0007 | B8: 1 | C8: 0
A9: P0008 | B9: 1 | C9: 0
A10: P0009 | B10: 1 | C10: 0
A11: P0010 | B11: 1 | C11: 0
A12: P0011 | B12: 1 | C12: 0
A13: P0012 | B13: 1 | C13: 0
... A73: P0072 | B73: 1 | C73: 1

Sheet Partner_Info
A1: Partner_ID | B1: Partner_Name | C1: Gender | D1: Email | E1: PhoneNumber | F1: Ward/Commune | G1: Province/City | H1: Birthday
A2: P0001 | B2: Nguyễn Thị Vân Anh | C2: 1 | D2: vant@gmail.com | E2: 0962735841 | F2: Phường Bến Nghé | G2: Thành phố Hồ Chí Minh | H2: 38275
A3: P0002 | B3: Trương Đức Mạnh | C3: 0 | D3: manhtd@gmail.com | E3: 0283776251 | F3: Phường Gò Vấp | G3: Thành phố Hồ Chí Minh | H3: 22045
A4: P0003 | B4: Nguyễn Minh Nghĩa | C4: 0 | D4: nghianm@gmail.com | E4: 0862735791 | F4: Xã Yên Xuân | G4: Tỉnh Nghệ An | H4: 803
A5: P0004 | B5: Trần Thiên Hạo | E5: 0962871435 | H5: 28720
A6: P0005 | B6: Phí Minh Quang | C6: 0 | D6: quangpm@gmail.com | E6: 0829346501 | F6: Phường Trảng Dài | G6: Tỉnh Đồng Nai | H6: 3181
A7: P0006 | B7: Nguyễn Ngọc Mỹ Kỳ | C7: 1 | D7: kynnm@gmail.com | E7: 0794562380 | F7: Phường Phú Nhuận | G7: Thành phố Hồ Chí Minh | H7: 44837
A8: P0007 | B8: Trần Ngọc My | E8: 0917823409 | H8: 36942
A9: P0008 | B9: Phí Quỳnh Anh | C9: 1 | D9: anhpq@gmail.com | E9: 0832149760 | F9: Phường Đồng Xuân | G9: Thành phố Hà Nội | H9: 12226
A10: P0009 | B10: Bùi Bích Phương | C10: 1 | D10: phuongbb@gmail.com | E10: 0908231567 | F10: Phường Nguyễn Du | G10: Thành phố Hà Nội | H10: 36941
A11: P0010 | B11: Trần Nhã Uyên | C11: 1 | D11: uyentn@gmail.com | E11: 0283912048 | F11: Phường Hòa Cường Nam | G11: Thành phố Đà Nẵng | H11: 39392
A12: P0011 | B12: Lê Ngọc Hân | C12: 1 | D12: hanln@gmail.com | E12: 0931678201 | F12: Phường Đồng Hới | G12: Tỉnh Quảng Trị | H12: 26219
A13: P0012 | B13: Châu Đan Hạnh | E13: 0875204319 | H13: 21269
A14: P0013 | B14: Trần Văn Thắng | C14: 0 | D14: thangtv@gmail.com | E14: 0971048362 | F14: Phường Kim Liên | G14: Thành phố Hà Nội | H14: 39751
A15: P0014 | B15: Hoàng Anh Duy | C15: 0 | D15: duyha@gmail.com | E15: 0928457130 | F15: Phường Phú Lợi | G15: Thành phố Hồ Chí Minh | H15: 28032
A16: P0015 | B16: Nguyễn Thành Đạt | C16: 0 | D16: datnt@gmail.com | E16: 0843157092 | F16: Phường Vũng Tàu | G16: Thành phố Hồ Chí Minh | H16: 33006
A17: P0016 | B17: Lê Kiều Gia Hân | C17: 1 | D17: hanlkg@gmail.com | E17: 0298361470 | F17: Xã Tú Lệ | G17: Tỉnh Lào Cai | H17: 27714
A18: P0017 | B18: Nguyễn Mai Hân | E18: 0897402513 | H18: 36836
A19: P0018 | B19: Phạm Thị Hoàng Oanh | C19: 1 | D19: oanhpth@gmail.com | E19: 0813496725 | F19: Xã Minh Thạnh | G19: Thành phố Hồ Chí Minh | H19: 30579
A20: P0019 | B20: Nguyễn Hoàng Ly | C20: 1 | D20: lynh@gmail.com | E20: 0904628731 | F20: Phường Tràng An | G20: Thành phố Hà Nội | H20: 40195
A21: P0020 | B21: Bạch Ngọc My | C21: 1 | D21: mybn@gmail.com | E21: 0775396842 | F21: Phường Tăng Nhơn Phú | G21: Thành phố Hồ Chí Minh | H21: 32560
A22: P0021 | B22: Hồ Hoàn Mỹ | C22: 1 | D22: myhh@gmail.com | E22: 0937581206 | F22: Phường Võ Cường | G22: Tỉnh Bắc Ninh | H22: 45965
A23: P0022 | B23: Nguyễn Thùy Ngọc Hân | E23: 0869014328 | H23: 42477
A24: P0023 | B24: Phan Thị Tuyết Giang | E24: 0912435678 | H24: 10352
A25: P0024 | B25: Trần Thanh Nhàn | E25: 0987264309 | H25: 19838
A26: P0025 | B26: Võ Nguyễn Tường Vy | E26: 0817623495 | H26: 25579
A27: P0026 | B27: Nguyễn Đào Hồng Như | E27: 0920475832 | H27: 34323
A28: P0027 | B28: Lê Thị Minh Hằng | C28: 1 | D28: hangltm@gmail.com | E28: 0901862435 | F28: Phường Phú Hải | G28: Tỉnh Quảng Ninh | H28: 32604
A29: P0028 | B29: Nguyễn Lê Bảo Hân | C29: 1 | D29: hannlb@gmail.com | E29: 0827349160 | F29: Phường Tân Thạnh | G29: Tỉnh Long An | H29: 382
A30: P0029 | B30: Phan Thanh Mai | C30: 1 | D30: maipt@gmail.com | E30: 0982013476 | F30: Phường Đức Thắng | G30: Tỉnh Lâm Đồng | H30: 11786
A31: P0030 | B31: Trần Ngọc Mai | C31: 1 | D31: maitn@gmail.com | E31: 0965482130 | F31: Phường Hàm Rồng | G31: Tỉnh Thanh Hóa | H31: 17319
A32: P0031 | B32: Lữ Thị Đào | C32: 1 | D32: daoltt@gmail.com | E32: 0830947512 | F32: Phường Hải Thành | G32: Tỉnh Đồng Nai | H32: 16375
A33: P0032 | B33: Trần Tấn Tài | C33: 0 | D33: taitt@gmail.com | E33: 0936872041 | F33: Xã Hiếu Phụng | G33: Tỉnh Vĩnh Long | H33: 30018
A34: P0033 | B34: Trần Anh Khôi | C34: 0 | D34: khoita@gmail.com | E34: 0891306452 | F34: Phường Vĩnh Hòa | G34: Tỉnh Khánh Hòa | H34: 45196
A35: P0034 | B35: Nguyễn Hoàng Huy | E35: 0704957126 | H35: 35049
A36: P0035 | B36: Võ Tấn Huy | E36: 0704957127 | H36: 32358
A37: P0036 | B37: Lê Anh Kiệt | E37: 0704957129 | H37: 32309
A38: P0037 | B38: Nguyễn Thị Bảo Trân | C38: 1 | D38: tranntb@gmail.com | E38: 0968312045 | F38: Phường Xuân Hòa | G38: Thành phố Hồ Chí Minh | H38: 24521
A39: P0038 | B39: Trần Minh Khang | C39: 0 | D39: khangtm@gmail.com | E39: 0892341056 | F39: Phường Cái Răng | G39: Thành phố Cần Thơ | H39: 180
A40: P0039 | B40: Lê Ngọc Tuyền | C40: 1 | D40: tuyenln@gmail.com | E40: 0706548231 | F40: Phường Bình Thạnh | G40: Thành phố Hồ Chí Minh | H40: 21841
...

Sheet Store
A1: Store_ID | B1: Ward/Commune | C1: Province/City
A2: STO_001 | B2: Phường Sài Gòn | C2: Thành phố Hồ Chí Minh
A3: STO_002 | B3: Phường Đống Đa | C3: Thành phố Hà Nội
A4: STO_003 | B4: Phường Hưng Lợi | C4: Thành phố Cần Thơ
A5: STO_004 | B5: Phường Hòa Cường Nam | C5: Thành phố Đà Nẵng
A6: STO_005 | B6: Phường Hạnh Thông | C6: Thành phố Hồ Chí Minh
A7: STO_006 | B7: Phường Quán Toan | C7: Thành phố Hải Phòng

Sheet Employee
A1: Emp_ID | B1: Emp_Name | C1: PhoneNumber | D1: Store_ID | E1: Role
A2: EMP0001 | B2: Nguyễn Minh Tuấn | C2: 0901234561 | D2: STO_001 | E2: Manager
A3: EMP0002 | B3: Trần Thị Mai Anh | C3: 0902345672 | D3: STO_001 | E3: Manager
A4: EMP0003 | B4: Lê Văn Hưng | C4: 0903456783 | D4: STO_001 | E4: Manager
A5: EMP0004 | B5: Hà Thảo Anh | C5: 0977826315 | D5: STO_001 | E5: Staff
A6: EMP0005 | B6: Bùi Công Nam | C6: 0277817160 | D6: STO_001 | E6: Staff
A7: EMP0006 | B7: Lê Thanh Thảo Tâm | C7: 0891716235 | D7: STO_001 | E7: Staff
A8: EMP0007 | B8: Trần Thị Thu Hường | C8: 0812567100 | D8: STO_001 | E8: Staff
A9: EMP0008 | B9: Nguyễn Thảo Nguyên | C9: 0904567894 | D9: STO_002 | E9: Staff
A10: EMP0009 | B10: Phạm Đức Duy | C10: 0905678905 | D10: STO_002 | E10: Staff
A11: EMP0010 | B11: Lê Khánh Huyền | C11: 0906789016 | D11: STO_002 | E11: Staff
A12: EMP0011 | B12: Trần Quốc Bảo | C12: 0907890127 | D12: STO_002 | E12: Staff
... A30: EMP0029 | B30: Lý Gia Bảo | C30: 0925678905 | D30: STO_006 | E30: Staff

Sheet Category
A1: Category_ID | B1: Category_Name
A2: CAT0001 | B2: Áo thun
A3: CAT0002 | B3: Áo sơ mi
A4: CAT0003 | B4: Áo kiểu (croptop/tanktop/2 dây)
A5: CAT0004 | B5: Áo khoác
A6: CAT0005 | B6: Áo polo
A7: CAT0006 | B7: Áo hoodie, sweatshirt
A8: CAT0007 | B8: Quần short
A9: CAT0008 | B9: Quần dài
A10: CAT0009 | B10: Váy

Sheet Product
A1: Product_ID | B1: Partner_ID | C1: Product_Name | D1: Cat_ID | E1: Color | F1: Size | G1: Quantity | H1: ImportPrice | I1: ExportPrice
A2: SP000001 | B2: P0061 | C2: Áo sơ mi thắt eo | D2: CAT0002 | E2: Trắng | F2: XS | G2: 324 | H2: 120000 | I2: 250000
A3: SP000002 | B3: P0061 | C3: Áo sơ mi thắt eo | D3: CAT0002 | E3: Trắng | F3: S | G3: 549 | H3: 120000 | I3: 250000
A4: SP000003 | B4: P0061 | C4: Áo sơ mi thắt eo | D4: CAT0002 | E4: Trắng | F4: M | G4: 372 | H4: 120000 | I4: 250000
A5: SP000004 | B5: P0061 | C5: Áo sơ mi thắt eo | D5: CAT0002 | E5: Trắng | F5: L | G5: 606 | H5: 120000 | I5: 250000
A6: SP000005 | B6: P0061 | C6: Áo sơ mi cộc tay poly rayon xám form regular | D6: CAT0002 | E6: Xám | F6: S | G6: 394 | H6: 90000 | I6: 200000
A7: SP000006 | B7: P0061 | C7: Áo sơ mi cộc tay poly rayon xám form regular | D7: CAT0002 | E7: Xám | F7: M | G7: 347 | H7: 90000 | I7: 200000
A8: SP000007 | B8: P0061 | C8: Áo sơ mi cộc tay poly rayon xám form regular | D8: CAT0002 | E8: Xám | F8: L | G8: 564 | H8: 90000 | I8: 200000
A9: SP000008 | B9: P0061 | C9: Áo sơ mi cộc tay poly rayon xám form regular | D9: CAT0002 | E9: Xám | F9: XL | G9: 713 | H9: 90000 | I9: 200000
A10: SP000009 | B10: P0061 | C10: Áo sơ mi cộc tay poly rayon xám form regular | D10: CAT0002 | E10: Xám | F10: XXL | G10: 340 | H10: 90000 | I10: 200000
A11: SP000010 | B11: P0061 | C11: Áo sơ mi cộc tay poly rayon xám form regular | D11: CAT0002 | E11: Xanh than | F11: S | G11: 59 | H11: 90000 | I11: 200000
A12: SP000011 | B12: P0061 | C12: Áo sơ mi cộc tay poly rayon xám form regular | D12: CAT0002 | E12: Xanh than | F12: M | G12: 698 | H12: 90000 | I12: 200000
A13: SP000012 | B13: P0061 | C13: Áo sơ mi cộc tay poly rayon xám form regular | D13: CAT0002 | E13: Xanh than | F13: L | G13: 527 | H13: 90000 | I13: 200000
... A305: SP000304 | B305: P0072 | C305: Chân váy bí form nhỏ dáng ngắn cạp thấp | D305: CAT0008 | E305: Trắng | F305: Freesize < 60kg | G305: 500 | H305: 180000 | I305: 250000

Sheet Order
A1: Order_ID | B1: Store_ID | C1: Emp_ID | D1: Partner_ID | E1: Partner_Name | F1: Partner_Phone | G1: Create_Date | H1: SubTotal | I1: Discount_ID | J1: Discount_Percent | K1: Discount_Amount | L1: Total | M1: Shipping Ward/Commune | N1: Shipping Province/City | O1: Status | P1: Channel
A2: ORD00001 | B2: STO_005 | C2: EMP0006 | D2: P0001 | E2: Nguyễn Thị Vân Anh | F2: 962735841 | G2: 45689 | H2: 820000 | I2: =IF(AND(G2=DATE(2025,7,7), H2>=1000000), "DIS_003A", IF(AND(G2=DATE(2025,7,15), H2>=1000000), "DIS_003B", 0)) -> 0 | J2: =IF(AND(OR(G2=DATE(2025,7,7), G2=DATE(2025,7,15)), H2 >= 1000000), 20, 0) -> 0 | K2: =H2*J2% -> 0 | L2: =H2-K2 -> 820000 | M2: Phường Bến Nghé | N2: =IFERROR(VLOOKUP(B2, Store!$A:$C, 3, FALSE), "") -> Thành phố Hồ Chí Minh | O2: Đã hoàn thành | P2: Tiktokshop
A3: ORD00002 | B3: STO_002 | C3: EMP0019 | D3: P0011 | E3: Lê Ngọc Hân | F3: 931678201 | G3: 45689 | H3: 180000 | I3: =IF(AND(G3=DATE(2025,7,7), H3>=1000000), "DIS_003A", IF(AND(G3=DATE(2025,7,15), H3>=1000000), "DIS_003B", 0)) -> 0 | J3: =IF(AND(OR(G3=DATE(2025,7,7), G3=DATE(2025,7,15)), H3 >= 1000000), 20, 0) -> 0 | K3: =H3*J3% -> 0 | L3: =H3-K3 -> 180000 | M3: Phường Đồng Hới | N3: Tỉnh Quảng Trị | O3: Đã hoàn thành | P3: Tiktokshop
A4: ORD00003 | B4: STO_005 | C4: EMP0020 | D4: P0025 | E4: Võ Nguyễn Tường Vy | F4: 817623495 | G4: 45689 | H4: 735000 | I4: =IF(AND(G4=DATE(2025,7,7), H4>=1000000), "DIS_003A", IF(AND(G4=DATE(2025,7,15), H4>=1000000), "DIS_003B", 0)) -> 0 | J4: =IF(AND(OR(G4=DATE(2025,7,7), G4=DATE(2025,7,15)), H4 >= 1000000), 20, 0) -> 0 | K4: =H4*J4% -> 0 | L4: =H4-K4 -> 735000 | M4: Phường Sài Gòn | N4: =IFERROR(VLOOKUP(B4, Store!$A:$C, 3, FALSE), "") -> Thành phố Hồ Chí Minh | O4: Đã hoàn thành | P4: Tiktokshop
A5: ORD00004 | B5: STO_003 | C5: EMP0012 | D5: P0036 | E5: Lê Anh Kiệt | F5: 704957129 | G5: 45689 | H5: 360000 | I5: =IF(AND(G5=DATE(2025,7,7), H5>=1000000), "DIS_003A", IF(AND(G5=DATE(2025,7,15), H5>=1000000), "DIS_003B", 0)) -> 0 | J5: =IF(AND(OR(G5=DATE(2025,7,7), G5=DATE(2025,7,15)), H5 >= 1000000), 20, 0) -> 0 | K5: =H5*J5% -> 0 | L5: =H5-K5 -> 360000 | M5: Phường Cái Khế | N5: =IFERROR(VLOOKUP(B5, Store!$A:$C, 3, FALSE), "") -> Thành phố Cần Thơ | O5: Đã hoàn thành | P5: Tiktokshop
A6: ORD00005 | B6: STO_002 | C6: EMP0009 | D6: P0047 | E6: Nguyễn Thị Khánh Linh | F6: 869341028 | G6: 45689 | H6: 530000 | I6: =IF(AND(G6=DATE(2025,7,7), H6>=1000000), "DIS_003A", IF(AND(G6=DATE(2025,7,15), H6>=1000000), "DIS_003B", 0)) -> 0 | J6: =IF(AND(OR(G6=DATE(2025,7,7), G6=DATE(2025,7,15)), H6 >= 1000000), 20, 0) -> 0 | K6: =H6*J6% -> 0 | L6: =H6-K6 -> 530000 | M6: Phường Trà Lý | N6: Tỉnh Hưng Yên | O6: Đã hoàn thành | P6: Tiktokshop
A7: ORD00006 | B7: STO_002 | C7: EMP0005 | D7: P0058 | E7: Bùi Thảo Ly | F7: 823674901 | G7: 45689 | H7: 1000000 | I7: =IF(AND(G7=DATE(2025,7,7), H7>=1000000), "DIS_003A", IF(AND(G7=DATE(2025,7,15), H7>=1000000), "DIS_003B", 0)) -> 0 | J7: =IF(AND(OR(G7=DATE(2025,7,7), G7=DATE(2025,7,15)), H7 >= 1000000), 20, 0) -> 0 | K7: =H7*J7% -> 0 | L7: =H7-K7 -> 1000000 | M7: Phường Bàn Cờ | N7: =IFERROR(VLOOKUP(B7, Store!$A:$C, 3, FALSE), "") -> Thành phố Hà Nội | O7: Đã hoàn thành | P7: Tiktokshop
A8: ORD00007 | B8: STO_002 | C8: EMP0008 | D8: P0032 | E8: Trần Tấn Tài | F8: 936872041 | G8: 45689 | H8: 180000 | I8: =IF(AND(G8=DATE(2025,7,7), H8>=1000000), "DIS_003A", IF(AND(G8=DATE(2025,7,15), H8>=1000000), "DIS_003B", 0)) -> 0 | J8: =IF(AND(OR(G8=DATE(2025,7,7), G8=DATE(2025,7,15)), H8 >= 1000000), 20, 0) -> 0 | K8: =H8*J8% -> 0 | L8: =H8-K8 -> 180000 | M8: Phường Cửa Nam | N8: =IFERROR(VLOOKUP(B8, Store!$A:$C, 3, FALSE), "") -> Thành phố Hà Nội | O8: Đã hoàn thành | P8: Tiktokshop
A9: ORD00008 | B9: STO_005 | C9: EMP0001 | D9: P0020 | E9: Bạch Ngọc My | F9: 775396842 | G9: 45689 | H9: 460000 | I9: =IF(AND(G9=DATE(2025,7,7), H9>=1000000), "DIS_003A", IF(AND(G9=DATE(2025,7,15), H9>=1000000), "DIS_003B", 0)) -> 0 | J9: =IF(AND(OR(G9=DATE(2025,7,7), G9=DATE(2025,7,15)), H9 >= 1000000), 20, 0) -> 0 | K9: =H9*J9% -> 0 | L9: =H9-K9 -> 460000 | M9: Phường Tăng Nhơn Phú | N9: =IFERROR(VLOOKUP(B9, Store!$A:$C, 3, FALSE), "") -> Thành phố Hồ Chí Minh | O9: Đã hoàn thành | P9: Tiktokshop
A10: ORD00009 | B10: STO_002 | C10: EMP0008 | D10: P0031 | E10: Lữ Thị Đào | F10: 830947512 | G10: 45689 | H10: 360000 | I10: =IF(AND(G10=DATE(2025,7,7), H10>=1000000), "DIS_003A", IF(AND(G10=DATE(2025,7,15), H10>=1000000), "DIS_003B", 0)) -> 0 | J10: =IF(AND(OR(G10=DATE(2025,7,7), G10=DATE(2025,7,15)), H10 >= 1000000), 20, 0) -> 0 | K10: =H10*J10% -> 0 | L10: =H10-K10 -> 360000 | M10: Phường Cửa Nam | N10: =IFERROR(VLOOKUP(B10, Store!$A:$C, 3, FALSE), "") -> Thành phố Hà Nội | O10: Đã hoàn thành | P10: Tiktokshop
A11: ORD00010 | B11: STO_004 | C11: EMP0015 | D11: P0042 | E11: Đỗ Đức Thịnh | F11: 920346582 | G11: 45689 | H11: 235000 | I11: =IF(AND(G11=DATE(2025,7,7), H11>=1000000), "DIS_003A", IF(AND(G11=DATE(2025,7,15), H11>=1000000), "DIS_003B", 0)) -> 0 | J11: =IF(AND(OR(G11=DATE(2025,7,7), G11=DATE(2025,7,15)), H11 >= 1000000), 20, 0) -> 0 | K11: =H11*J11% -> 0 | L11: =H11-K11 -> 235000 | M11: Hải Châu | N11: =IFERROR(VLOOKUP(B11, Store!$A:$C, 3, FALSE), "") -> Thành phố Đà Nẵng | O11: Đã hoàn thành | P11: Tiktokshop
A12: ORD00011 | B12: STO_004 | C12: EMP0019 | D12: P0053 | E12: Nguyễn Hà My | F12: 879132460 | G12: 45690 | H12: 640000 | I12: =IF(AND(G12=DATE(2025,7,7), H12>=1000000), "DIS_003A", IF(AND(G12=DATE(2025,7,15), H12>=1000000), "DIS_003B", 0)) -> 0 | J12: =IF(AND(OR(G12=DATE(2025,7,7), G12=DATE(2025,7,15)), H12 >= 1000000), 20, 0) -> 0 | K12: =H12*J12% -> 0 | L12: =H12-K12 -> 640000 | M12: Phường An Hải | N12: =IFERROR(VLOOKUP(B12, Store!$A:$C, 3, FALSE), "") -> Thành phố Đà Nẵng | O12: Đã hoàn thành | P12: Tiktokshop
A13: ORD00012 | B13: STO_004 | C13: EMP0016 | D13: P0012 | E13: Châu Đan Hạnh | F13: 875204319 | G13: 45690 | H13: 380000 | I13: =IF(AND(G13=DATE(2025,7,7), H13>=1000000), "DIS_003A", IF(AND(G13=DATE(2025,7,15), H13>=1000000), "DIS_003B", 0)) -> 0 | J13: =IF(AND(OR(G13=DATE(2025,7,7), G13=DATE(2025,7,15)), H13 >= 1000000), 20, 0) -> 0 | K13: =H13*J13% -> 0 | L13: =H13-K13 -> 380000 | M13: An Hải | N13: =IFERROR(VLOOKUP(B13, Store!$A:$C, 3, FALSE), "") -> Thành phố Đà Nẵng | O13: Đã hoàn thành | P13: Tiktokshop
A14: ORD00013 | B14: STO_001 | C14: EMP0021 | D14: P0026 | E14: Nguyễn Đào Hồng Như | F14: 920475832 | G14: 45690 | H14: 500000 | I14: =IF(AND(G14=DATE(2025,7,7), H14>=1000000), "DIS_003A", IF(AND(G14=DATE(2025,7,15), H14>=1000000), "DIS_003B", 0)) -> 0 | J14: =IF(AND(OR(G14=DATE(2025,7,7), G14=DATE(2025,7,15)), H14 >= 1000000), 20, 0) -> 0 | K14: =H14*J14% -> 0 | L14: =H14-K14 -> 500000 | M14: Phường Bến Nghé | N14: =IFERROR(VLOOKUP(B14, Store!$A:$C, 3, FALSE), "") -> Thành phố Hồ Chí Minh | O14: Đã hoàn thành | P14: Tiktokshop
A15: ORD00014 | B15: STO_001 | C15: EMP0020 | D15: P0037 | E15: Nguyễn Thị Bảo Trân | F15: 968312045 | G15: 45690 | H15: 920000 | I15: =IF(AND(G15=DATE(2025,7,7), H15>=1000000), "DIS_003A", IF(AND(G15=DATE(2025,7,15), H15>=1000000), "DIS_003B", 0)) -> 0 | J15: =IF(AND(OR(G15=DATE(2025,7,7), G15=DATE(2025,7,15)), H15 >= 1000000), 20, 0) -> 0 | K15: =H15*J15% -> 0 | L15: =H15-K15 -> 920000 | M15: Phường Xuân Hòa | N15: =IFERROR(VLOOKUP(B15, Store!$A:$C, 3, FALSE), "") -> Thành phố Hồ Chí Minh | O15: Đã hoàn thành | P15: Tiktokshop
A16: ORD00015 | B16: STO_003 | C16: EMP0012 | D16: P0048 | E16: Phan Anh Tú | F16: 918273645 | G16: 45690 | H16: 1000000 | I16: =IF(AND(G16=DATE(2025,7,7), H16>=1000000), "DIS_003A", IF(AND(G16=DATE(2025,7,15), H16>=1000000), "DIS_003B", 0)) -> 0 | J16: =IF(AND(OR(G16=DATE(2025,7,7), G16=DATE(2025,7,15)), H16 >= 1000000), 20, 0) -> 0 | K16: =H16*J16% -> 0 | L16: =H16-K16 -> 1000000 | M16: Phường Cái Khế | N16: =IFERROR(VLOOKUP(B16, Store!$A:$C, 3, FALSE), "") -> Thành phố Cần Thơ | O16: Đã hoàn thành | P16: Tiktokshop
A17: ORD00016 | B17: STO_001 | C17: EMP0023 | D17: P0059 | E17: Hà Quang Huy | F17: 261735712 | G17: 45690 | H17: 960000 | I17: =IF(AND(G17=DATE(2025,7,7), H17>=1000000), "DIS_003A", IF(AND(G17=DATE(2025,7,15), H17>=1000000), "DIS_003B", 0)) -> 0 | J17: =IF(AND(OR(G17=DATE(2025,7,7), G17=DATE(2025,7,15)), H17 >= 1000000), 20, 0) -> 0 | K17: =H17*J17% -> 0 | L17: =H17-K17 -> 960000 | M17: Phường Tân Định | N17: =IFERROR(VLOOKUP(B17, Store!$A:$C, 3, FALSE), "") -> Thành phố Hồ Chí Minh | O17: Đã hoàn thành | P17: Tiktokshop
A18: ORD00017 | B18: STO_006 | C18: EMP0011 | D18: P0046 | E18: Trịnh Quốc Huy | F18: 973569840 | G18: 45690 | H18: 230000 | I18: =IF(AND(G18=DATE(2025,7,7), H18>=1000000), "DIS_003A", IF(AND(G18=DATE(2025,7,15), H18>=1000000), "DIS_003B", 0)) -> 0 | J18: =IF(AND(OR(G18=DATE(2025,7,7), G18=DATE(2025,7,15)), H18 >= 1000000), 20, 0) -> 0 | K18: =H18*J18% -> 0 | L18: =H18-K18 -> 230000 | M18: Xã Nam Sơn | N18: Tỉnh Bắc Ninh | O18: Đã hoàn thành | P18: Tiktokshop
A19: ORD00018 | B19: STO_006 | C19: EMP0010 | D19: P0021 | E19: Hồ Hoàn Mỹ | F19: 937581206 | G19: 45691 | H19: 960000 | I19: =IF(AND(G19=DATE(2025,7,7), H19>=1000000), "DIS_003A", IF(AND(G19=DATE(2025,7,15), H19>=1000000), "DIS_003B", 0)) -> 0 | J19: =IF(AND(OR(G19=DATE(2025,7,7), G19=DATE(2025,7,15)), H19 >= 1000000), 20, 0) -> 0 | K19: =H19*J19% -> 0 | L19: =H19-K19 -> 960000 | M19: Phường Võ Cường | N19: Tỉnh Bắc Ninh | O19: Đã hoàn thành | P19: Shopee
A20: ORD00019 | B20: STO_003 | C20: EMP0021 | D20: P0032 | E20: Trần Tấn Tài | F20: 936872041 | G20: 45691 | H20: 970000 | I20: =IF(AND(G20=DATE(2025,7,7), H20>=1000000), "DIS_003A", IF(AND(G20=DATE(2025,7,15), H20>=1000000), "DIS_003B", 0)) -> 0 | J20: =IF(AND(OR(G20=DATE(2025,7,7), G20=DATE(2025,7,15)), H20 >= 1000000), 20, 0) -> 0 | K20: =H20*J20% -> 0 | L20: =H20-K20 -> 970000 | M20: Xã Hiếu Phụng | N20: Tỉnh Vĩnh Long | O20: Đã hoàn thành | P20: Shopee
A21: ORD00020 | B21: STO_004 | C21: EMP0016 | D21: P0043 | E21: Lê Hồng Nhung | F21: 987653412 | G21: 45691 | H21: 735000 | I21: =IF(AND(G21=DATE(2025,7,7), H21>=1000000), "DIS_003A", IF(AND(G21=DATE(2025,7,15), H21>=1000000), "DIS_003B", 0)) -> 0 | J21: =IF(AND(OR(G21=DATE(2025,7,7), G21=DATE(2025,7,15)), H21 >= 1000000), 20, 0) -> 0 | K21: =H21*J21% -> 0 | L21: =H21-K21 -> 735000 | M21: An Khê | N21: =IFERROR(VLOOKUP(B21, Store!$A:$C, 3, FALSE), "") -> Thành phố Đà Nẵng | O21: Đã hoàn thành | P21: Shopee
A22: ORD00021 | B22: STO_004 | C22: EMP0016 | D22: P0054 | E22: Trần Thanh Long | F22: 839201476 | G22: 45691 | H22: 970000 | I22: =IF(AND(G22=DATE(2025,7,7), H22>=1000000), "DIS_003A", IF(AND(G22=DATE(2025,7,15), H22>=1000000), "DIS_003B", 0)) -> 0 | J22: =IF(AND(OR(G22=DATE(2025,7,7), G22=DATE(2025,7,15)), H22 >= 1000000), 20, 0) -> 0 | K22: =H22*J22% -> 0 | L22: =H22-K22 -> 970000 | M22: An Hải | N22: =IFERROR(VLOOKUP(B22, Store!$A:$C, 3, FALSE), "") -> Thành phố Đà Nẵng | O22: Đã hoàn thành | P22: Shopee
A23: ORD00022 | B23: STO_004 | C23: EMP0018 | D23: P0009 | E23: Bùi Bích Phương | F23: 908231567 | G23: 45691 | H23: 735000 | I23: =IF(AND(G23=DATE(2025,7,7), H23>=1000000), "DIS_003A", IF(AND(G23=DATE(2025,7,15), H23>=1000000), "DIS_003B", 0)) -> 0 | J23: =IF(AND(OR(G23=DATE(2025,7,7), G23=DATE(2025,7,15)), H23 >= 1000000), 20, 0) -> 0 | K23: =H23*J23% -> 0 | L23: =H23-K23 -> 735000 | M23: An Hải | N23: =IFERROR(VLOOKUP(B23, Store!$A:$C, 3, FALSE), "") -> Thành phố Đà Nẵng | O23: Đã hoàn thành | P23: Shopee
A24: ORD00023 | B24: STO_006 | C24: EMP0011 | D24: P0057 | E24: Lê Thị Minh Trang | F24: 971348025 | G24: 45691 | H24: 1380000 | I24: =IF(AND(G24=DATE(2025,7,7), H24>=1000000), "DIS_003A", IF(AND(G24=DATE(2025,7,15), H24>=1000000), "DIS_003B", 0)) -> 0 | J24: =IF(AND(OR(G24=DATE(2025,7,7), G24=DATE(2025,7,15)), H24 >= 1000000), 20, 0) -> 0 | K24: =H24*J24% -> 0 | L24: =H24-K24 -> 1380000 | M24: Phường Hạc Thành | N24: Tỉnh Thanh Hóa | O24: Đã hoàn thành | P24: Shopee
A25: ORD00024 | B25: STO_001 | C25: EMP0004 | D25: P0012 | E25: Châu Đan Hạnh | F25: 875204319 | G25: 45691 | H25: 920000 | I25: =IF(AND(G25=DATE(2025,7,7), H25>=1000000), "DIS_003A", IF(AND(G25=DATE(2025,7,15), H25>=1000000), "DIS_003B", 0)) -> 0 | J25: =IF(AND(OR(G25=DATE(2025,7,7), G25=DATE(2025,7,15)), H25 >= 1000000), 20, 0) -> 0 | K25: =H25*J25% -> 0 | L25: =H25-K25 -> 920000 | M25: Phường Khánh Hội | N25: =IFERROR(VLOOKUP(B25, Store!$A:$C, 3, FALSE), "") -> Thành phố Hồ Chí Minh | O25: Đã hoàn thành | P25: Shopee
A26: ORD00025 | B26: STO_001 | C26: EMP0003 | D26: P0023 | E26: Phan Thị Tuyết Giang | F26: 912435678 | G26: 45691 | H26: 1175000 | I26: =IF(AND(G26=DATE(2025,7,7), H26>=1000000), "DIS_003A", IF(AND(G26=DATE(2025,7,15), H26>=1000000), "DIS_003B", 0)) -> 0 | J26: =IF(AND(OR(G26=DATE(2025,7,7), G26=DATE(2025,7,15)), H26 >= 1000000), 20, 0) -> 0 | K26: =H26*J26% -> 0 | L26: =H26-K26 -> 1175000 | M26: Phường Khánh Hội | N26: =IFERROR(VLOOKUP(B26, Store!$A:$C, 3, FALSE), "") -> Thành phố Hồ Chí Minh | O26: Đã hoàn thành | P26: Shopee
A27: ORD00026 | B27: STO_002 | C27: EMP0008 | D27: P0034 | E27: Nguyễn Hoàng Huy | F27: 704957126 | G27: 45691 | H27: 955000 | I27: =IF(AND(G27=DATE(2025,7,7), H27>=1000000), "DIS_003A", IF(AND(G27=DATE(2025,7,15), H27>=1000000), "DIS_003B", 0)) -> 0 | J27: =IF(AND(OR(G27=DATE(2025,7,7), G27=DATE(2025,7,15)), H27 >= 1000000), 20, 0) -> 0 | K27: =H27*J27% -> 0 | L27: =H27-K27 -> 955000 | M27: Phường Ba Đình | N27: =IFERROR(VLOOKUP(B27, Store!$A:$C, 3, FALSE), "") -> Thành phố Hà Nội | O27: Đã hoàn thành | P27: Shopee
A28: ORD00027 | B28: STO_001 | C28: EMP0006 | D28: P0045 | E28: Huỳnh Mỹ Duyên | F28: 901245786 | G28: 45720 | H28: 1250000 | I28: =IF(AND(G28=DATE(2025,7,7), H28>=1000000), "DIS_003A", IF(AND(G28=DATE(2025,7,15), H28>=1000000), "DIS_003B", 0)) -> 0 | J28: =IF(AND(OR(G28=DATE(2025,7,7), G28=DATE(2025,7,15)), H28 >= 1000000), 20, 0) -> 0 | K28: =H28*J28% -> 0 | L28: =H28-K28 -> 1250000 | M28: Xã Nhà Bè | N28: =IFERROR(VLOOKUP(B28, Store!$A:$C, 3, FALSE), "") -> Thành phố Hồ Chí Minh | O28: Đã hoàn thành | P28: Shopee
A29: ORD00028 | B29: STO_006 | C29: EMP0007 | D29: P0056 | E29: Phan Mạnh Quỳnh | F29: 916472309 | G29: 45720 | H29: 1750000 | I29: =IF(AND(G29=DATE(2025,7,7), H29>=1000000), "DIS_003A", IF(AND(G29=DATE(2025,7,15), H29>=1000000), "DIS_003B", 0)) -> 0 | J29: =IF(AND(OR(G29=DATE(2025,7,7), G29=DATE(2025,7,15)), H29 >= 1000000), 20, 0) -> 0 | K29: =H29*J29% -> 0 | L29: =H29-K29 -> 1750000 | M29: Xã Nam Minh | N29: Tỉnh Ninh Bình | O29: Đã hoàn thành | P29: Shopee
A30: ORD00029 | B30: STO_002 | C30: EMP0009 | D30: P0060 | E30: Lưu Diệc Phi | F30: 869341028 | G30: 45720 | H30: 800000 | I30: =IF(AND(G30=DATE(2025,7,7), H30>=1000000), "DIS_003A", IF(AND(G30=DATE(2025,7,15), H30>=1000000), "DIS_003B", 0)) -> 0 | J30: =IF(AND(OR(G30=DATE(2025,7,7), G30=DATE(2025,7,15)), H30 >= 1000000), 20, 0) -> 0 | K30: =H30*J30% -> 0 | L30: =H30-K30 -> 800000 | M30: Phường Cửa Nam | N30: =IFERROR(VLOOKUP(B30, Store!$A:$C, 3, FALSE), "") -> Thành phố Hà Nội | O30: Đã hoàn thành | P30: Shopee
A31: ORD00030 | B31: STO_002 | C31: EMP0009 | D31: P0013 | E31: Trần Văn Thắng | F31: 971048362 | G31: 45720 | H31: 1000000 | I31: =IF(AND(G31=DATE(2025,7,7), H31>=1000000), "DIS_003A", IF(AND(G31=DATE(2025,7,15), H31>=1000000), "DIS_003B", 0)) -> 0 | J31: =IF(AND(OR(G31=DATE(2025,7,7), G31=DATE(2025,7,15)), H31 >= 1000000), 20, 0) -> 0 | K31: =H31*J31% -> 0 | L31: =H31-K31 -> 1000000 | M31: Phường Kim Liên | N31: =IFERROR(VLOOKUP(B31, Store!$A:$C, 3, FALSE), "") -> Thành phố Hà Nội | O31: Đã hoàn thành | P31: Shopee
A32: ORD00031 | B32: STO_002 | C32: EMP0011 | D32: P0024 | E32: Trần Thanh Nhàn | F32: 987264309 | G32: 45720 | H32: 600000 | I32: =IF(AND(G32=DATE(2025,7,7), H32>=1000000), "DIS_003A", IF(AND(G32=DATE(2025,7,15), H32>=1000000), "DIS_003B", 0)) -> 0 | J32: =IF(AND(OR(G32=DATE(2025,7,7), G32=DATE(2025,7,15)), H32 >= 1000000), 20, 0) -> 0 | K32: =H32*J32% -> 0 | L32: =H32-K32 -> 600000 | M32: Phường Giảng Võ | N32: =IFERROR(VLOOKUP(B32, Store!$A:$C, 3, FALSE), "") -> Thành phố Hà Nội | O32: Đã hoàn thành | P32: Shopee
A33: ORD00032 | B33: STO_002 | C33: EMP0009 | D33: P0035 | E33: Võ Tấn Huy | F33: 704957127 | G33: 45720 | H33: 600000 | I33: =IF(AND(G33=DATE(2025,7,7), H33>=1000000), "DIS_003A", IF(AND(G33=DATE(2025,7,15), H33>=1000000), "DIS_003B", 0)) -> 0 | J33: =IF(AND(OR(G33=DATE(2025,7,7), G33=DATE(2025,7,15)), H33 >= 1000000), 20, 0) -> 0 | K33: =H33*J33% -> 0 | L33: =H33-K33 -> 600000 | M33: Phường Ba Đình | N33: =IFERROR(VLOOKUP(B33, Store!$A:$C, 3, FALSE), "") -> Thành phố Hà Nội | O33: Đã hoàn thành | P33: Shopee
A34: ORD00033 | B34: STO_002 | C34: EMP0010 | D34: P0046 | E34: Trịnh Quốc Huy | F34: 973569840 | G34: 45720 | H34: 900000 | I34: =IF(AND(G34=DATE(2025,7,7), H34>=1000000), "DIS_003A", IF(AND(G34=DATE(2025,7,15), H34>=1000000), "DIS_003B", 0)) -> 0 | J34: =IF(AND(OR(G34=DATE(2025,7,7), G34=DATE(2025,7,15)), H34 >= 1000000), 20, 0) -> 0 | K34: =H34*J34% -> 0 | L34: =H34-K34 -> 900000 | M34: Phường Ba Đình | N34: =IFERROR(VLOOKUP(B34, Store!$A:$C, 3, FALSE), "") -> Thành phố Hà Nội | O34: Đã hoàn thành | P34: Shopee
A35: ORD00034 | B35: STO_006 | C35: EMP0011 | D35: P0057 | E35: Lê Thị Minh Trang | F35: 971348025 | G35: 45720 | H35: 720000 | I35: =IF(AND(G35=DATE(2025,7,7), H35>=1000000), "DIS_003A", IF(AND(G35=DATE(2025,7,15), H35>=1000000), "DIS_003B", 0)) -> 0 | J35: =IF(AND(OR(G35=DATE(2025,7,7), G35=DATE(2025,7,15)), H35 >= 1000000), 20, 0) -> 0 | K35: =H35*J35% -> 0 | L35: =H35-K35 -> 720000 | M35: Phường Hạc Thành | N35: Tỉnh Thanh Hóa | O35: Đã hoàn thành | P35: Shopee
A36: ORD00035 | B36: STO_006 | C36: EMP0028 | D36: P0022 | E36: Nguyễn Thùy Ngọc Hân | F36: 968312045 | G36: 45752 | H36: 900000 | I36: =IF(AND(G36=DATE(2025,7,7), H36>=1000000), "DIS_003A", IF(AND(G36=DATE(2025,7,15), H36>=1000000), "DIS_003B", 0)) -> 0 | J36: =IF(AND(OR(G36=DATE(2025,7,7), G36=DATE(2025,7,15)), H36 >= 1000000), 20, 0) -> 0 | K36: =H36*J36% -> 0 | L36: =H36-K36 -> 900000 | M36: Lê Chân | N36: =IFERROR(VLOOKUP(B36, Store!$A:$C, 3, FALSE), "") -> Thành phố Hải Phòng | O36: Đã hoàn thành | P36: Shopee
A37: ORD00036 | B37: STO_003 | C37: EMP0012 | D37: P0014 | E37: Hoàng Anh Duy | F37: 928457130 | G37: 45752 | H37: 540000 | I37: =IF(AND(G37=DATE(2025,7,7), H37>=1000000), "DIS_003A", IF(AND(G37=DATE(2025,7,15), H37>=1000000), "DIS_003B", 0)) -> 0 | J37: =IF(AND(OR(G37=DATE(2025,7,7), G37=DATE(2025,7,15)), H37 >= 1000000), 20, 0) -> 0 | K37: =H37*J37% -> 0 | L37: =H37-K37 -> 540000 | M37: phường Tân An | N37: =IFERROR(VLOOKUP(B37, Store!$A:$C, 3, FALSE), "") -> Thành phố Cần Thơ | O37: Đã hoàn thành | P37: Shopee
A38: ORD00037 | B38: STO_006 | C38: EMP0026 | D38: P0025 | E38: Võ Nguyễn Tường Vy | F38: 817623495 | G38: 45752 | H38: 900000 | I38: =IF(AND(G38=DATE(2025,7,7), H38>=1000000), "DIS_003A", IF(AND(G38=DATE(2025,7,15), H38>=1000000), "DIS_003B", 0)) -> 0 | J38: =IF(AND(OR(G38=DATE(2025,7,7), G38=DATE(2025,7,15)), H38 >= 1000000), 20, 0) -> 0 | K38: =H38*J38% -> 0 | L38: =H38-K38 -> 900000 | M38: Lê Chân | N38: =IFERROR(VLOOKUP(B38, Store!$A:$C, 3, FALSE), "") -> Thành phố Hải Phòng | O38: Đã hoàn thành | P38: Shopee
A39: ORD00038 | B39: STO_005 | C39: EMP0005 | D39: P0036 | E39: Lê Anh Kiệt | F39: 704957129 | G39: 45752 | H39: 780000 | I39: =IF(AND(G39=DATE(2025,7,7), H39>=1000000), "DIS_003A", IF(AND(G39=DATE(2025,7,15), H39>=1000000), "DIS_003B", 0)) -> 0 | J39: =IF(AND(OR(G39=DATE(2025,7,7), G39=DATE(2025,7,15)), H39 >= 1000000), 20, 0) -> 0 | K39: =H39*J39% -> 0 | L39: =H39-K39 -> 780000 | M39: Phường Tân Mỹ | N39: =IFERROR(VLOOKUP(B39, Store!$A:$C, 3, FALSE), "") -> Thành phố Hồ Chí Minh | O39: Đã hoàn thành | P39: Shopee
A40: ORD00039 | B40: STO_005 | C40: EMP0006 | D40: P0047 | E40: Nguyễn Thị Khánh Linh | F40: 869341028 | G40: 45752 | H40: 780000 | I40: =IF(AND(G40=DATE(2025,7,7), H40>=1000000), "DIS_003A", IF(AND(G40=DATE(2025,7,15), H40>=1000000), "DIS_003B", 0)) -> 0 | J40: =IF(AND(OR(G40=DATE(2025,7,7), G40=DATE(2025,7,15)), H40 >= 1000000), 20, 0) -> 0 | K40: =H40*J40% -> 0 | L40: =H40-K40 -> 780000 | M40: Phường Gò Vấp | N40: =IFERROR(VLOOKUP(B40, Store!$A:$C, 3, FALSE), "") -> Thành phố Hồ Chí Minh | O40: Đã hoàn thành | P40: Shopee
...

Sheet Order_Detail
A1: OrderDetails_ID | B1: Order_ID | C1: Product_ID | D1: Product_Name | E1: Color | F1: Size | G1: Quantity | H1: PriceAtOrderTime | I1: Discount_ID | J1: Total
A2: 1 | B2: ORD00001 | C2: SP000003 | D2: Áo sơ mi thắt eo | E2: Trắng | F2: M | G2: 2 | H2: 250000 | I2: =IF(AND(ISNUMBER(MATCH(C2, Discount_Product_Apply!$B$2:$B$30, 0)), G2>=3, Order!G2>=DATE(2025,7,1), Order!G2<=DATE(2025,7,11)), "DIS_004", "") | J2: =IF(I2="DIS_004", INT(G2/3)*500000 + MOD(G2,3)*H2, H2*G2) -> 500000
A3: 2 | B3: ORD00001 | C3: SP000284 | D3: Chân váy chữ A công sở | E3: Đen | F3: M | G3: 1 | H3: 320000 | I3: =IF(AND(ISNUMBER(MATCH(C3, Discount_Product_Apply!$B$2:$B$30, 0)), G3>=3, Order!G3>=DATE(2025,7,1), Order!G3<=DATE(2025,7,11)), "DIS_004", "") | J3: =IF(I3="DIS_004", INT(G3/3)*500000 + MOD(G3,3)*H3, H3*G3) -> 320000
A4: 3 | B4: ORD00002 | C4: SP000016 | D4: Áo sơ mi tay ngắn tape trang trí | E4: Trắng sọc | F4: M | G4: 1 | H4: 180000 | I4: =IF(AND(ISNUMBER(MATCH(C4, Discount_Product_Apply!$B$2:$B$30, 0)), G4>=3, Order!G4>=DATE(2025,7,1), Order!G4<=DATE(2025,7,11)), "DIS_004", "") | J4: =IF(I4="DIS_004", INT(G4/3)*500000 + MOD(G4,3)*H4, H4*G4) -> 180000
A5: 4 | B5: ORD00003 | C5: SP000025 | D5: Áo thun tay ngắn cotton form regular cổ tròn | E5: Trắng | F5: S | G5: 3 | H5: 230000 | I5: =IF(AND(ISNUMBER(MATCH(C5, Discount_Product_Apply!$B$2:$B$30, 0)), G5>=3, Order!G5>=DATE(2025,7,1), Order!G5<=DATE(2025,7,11)), "DIS_004", "") | J5: =IF(I5="DIS_004", INT(G5/3)*500000 + MOD(G5,3)*H5, H5*G5) -> 690000
A6: 5 | B6: ORD00003 | C6: SP000050 | D6: Áo thun tay ngắn cổ vuông.Fitted Cropped | E6: Hồng pastel | F6: S | G6: 1 | H6: 235000 | I6: =IF(AND(ISNUMBER(MATCH(C6, Discount_Product_Apply!$B$2:$B$30, 0)), G6>=3, Order!G6>=DATE(2025,7,1), Order!G6<=DATE(2025,7,11)), "DIS_004", "") | J6: =IF(I6="DIS_004", INT(G6/3)*500000 + MOD(G6,3)*H6, H6*G6) -> 235000
A7: 6 | B7: ORD00004 | C7: SP000035 | D7: Áo thun tay ngắn sọc ngang | E7: Đen sọc trắng | F7: S | G7: 2 | H7: 180000 | I7: =IF(AND(ISNUMBER(MATCH(C7, Discount_Product_Apply!$B$2:$B$30, 0)), G7>=3, Order!G7>=DATE(2025,7,1), Order!G7<=DATE(2025,7,11)), "DIS_004", "") | J7: =IF(I7="DIS_004", INT(G7/3)*500000 + MOD(G7,3)*H7, H7*G7) -> 360000
A8: 7 | B8: ORD00005 | C8: SP000273 | D8: Quần dài kaki Wide leg | E8: Be | F8: S | G8: 2 | H8: 265000 | I8: =IF(AND(ISNUMBER(MATCH(C8, Discount_Product_Apply!$B$2:$B$30, 0)), G8>=3, Order!G8>=DATE(2025,7,1), Order!G8<=DATE(2025,7,11)), "DIS_004", "") | J8: =IF(I8="DIS_004", INT(G8/3)*500000 + MOD(G8,3)*H8, H8*G8) -> 530000
A9: 8 | B9: ORD00006 | C9: SP000001 | D9: Áo sơ mi thắt eo | E9: Trắng | F9: XS | G9: 4 | H9: 250000 | I9: =IF(AND(ISNUMBER(MATCH(C9, Discount_Product_Apply!$B$2:$B$30, 0)), G9>=3, Order!G9>=DATE(2025,7,1), Order!G9<=DATE(2025,7,11)), "DIS_004", "") | J9: =IF(I9="DIS_004", INT(G9/3)*500000 + MOD(G9,3)*H9, H9*G9) -> 1000000
A10: 9 | B10: ORD00007 | C10: SP000045 | D10: Áo thun tay ngắn sọc ngang | E10: Be | F10: S | G10: 1 | H10: 180000 | I10: =IF(AND(ISNUMBER(MATCH(C10, Discount_Product_Apply!$B$2:$B$30, 0)), G10>=3, Order!G10>=DATE(2025,7,1), Order!G10<=DATE(2025,7,11)), "DIS_004", "") | J10: =IF(I10="DIS_004", INT(G10/3)*500000 + MOD(G10,3)*H10, H10*G10) -> 180000
A11: 10 | B11: ORD00008 | C11: SP000026 | D11: Áo thun tay ngắn cotton form regular cổ tròn | E11: Trắng | F11: M | G11: 2 | H11: 230000 | I11: =IF(AND(ISNUMBER(MATCH(C11, Discount_Product_Apply!$B$2:$B$30, 0)), G11>=3, Order!G11>=DATE(2025,7,1), Order!G11<=DATE(2025,7,11)), "DIS_004", "") | J11: =IF(I11="DIS_004", INT(G11/3)*500000 + MOD(G11,3)*H11, H11*G11) -> 460000
A12: 11 | B12: ORD00009 | C12: SP000036 | D12: Áo thun tay ngắn sọc ngang | E12: Đen sọc trắng | F12: M | G12: 2 | H12: 180000 | I12: =IF(AND(ISNUMBER(MATCH(C12, Discount_Product_Apply!$B$2:$B$30, 0)), G12>=3, Order!G12>=DATE(2025,7,1), Order!G12<=DATE(2025,7,11)), "DIS_004", "") | J12: =IF(I12="DIS_004", INT(G12/3)*500000 + MOD(G12,3)*H12, H12*G12) -> 360000
A13: 12 | B13: ORD00010 | C13: SP000051 | D13: Áo thun tay ngắn cổ vuông.Fitted Cropped | E13: Hồng pastel | F13: M | G13: 1 | H13: 235000 | I13: =IF(AND(ISNUMBER(MATCH(C13, Discount_Product_Apply!$B$2:$B$30, 0)), G13>=3, Order!G13>=DATE(2025,7,1), Order!G13<=DATE(2025,7,11)), "DIS_004", "") | J13: =IF(I13="DIS_004", INT(G13/3)*500000 + MOD(G13,3)*H13, H13*G13) -> 235000
... A82: 81 | B82: ORD00047 | C82: SP000078 | D82: Quần dài kaki Wide leg | E82: Trắng | F82: XXL | G82: 3 | H82: 230000 | I82: =IF(AND(ISNUMBER(MATCH(C82, Discount_Product_Apply!$B$2:$B$30, 0)), G82>=3, Order!G82>=DATE(2025,7,1), Order!G82<=DATE(2025,7,11)), "DIS_004", "") -> DIS_004 | J82: =IF(I82="DIS_004", INT(G82/3)*500000 + MOD(G82,3)*H82, H82*G82) -> 500000
A83: 82 | B83: ORD00048 | C83: SP000289 | D83: Chân váy chữ A công sở | E83: Be | F83: M | G83: 1 | H83: 320000 | J83: =IF(I83="DIS_004", INT(G83/3)*500000 + MOD(G83,3)*H83, H83*G83) -> 320000
A84: 83 | B84: ORD00049 | C84: SP000262 | D84: Quần short nylon vải dù túi đắp relax | E84: Rêu | F84: XXL | G84: 2 | H84: 155000 | J84: =IF(I84="DIS_004", INT(G84/3)*500000 + MOD(G84,3)*H84, H84*G84) -> 310000
A85: 84 | B85: ORD00050 | C85: SP000001 | D85: Áo sơ mi thắt eo | E85: Trắng | F85: XS | G85: 1 | H85: 250000 | I85: =IF(AND(ISNUMBER(MATCH(C85, Discount_Product_Apply!$B$2:$B$30, 0)), G85>=3), "DIS_004", "") | J85: =IF(I85="DIS_004", INT(G85/3)*500000 + MOD(G85,3)*H85, H85*G85) -> 250000
A86: 85 | B86: ORD00051 | C86: SP000002 | D86: Áo sơ mi thắt eo | E86: Trắng | F86: S | G86: 3 | H86: 250000 | I86: =IF(AND(ISNUMBER(MATCH(C86, Discount_Product_Apply!$B$2:$B$30, 0)), G86>=3), "DIS_004", "") | J86: =IF(I86="DIS_004", INT(G86/3)*500000 + MOD(G86,3)*H86, H86*G86) -> 750000
A87: 86 | B87: ORD00051 | C87: SP000003 | D87: Áo sơ mi thắt eo | E87: Trắng | F87: M | G87: 2 | H87: 250000 | I87: =IF(AND(ISNUMBER(MATCH(C87, Discount_Product_Apply!$B$2:$B$30, 0)), G87>=3), "DIS_004", "") | J87: =IF(I87="DIS_004", INT(G87/3)*500000 + MOD(G87,3)*H87, H87*G87) -> 500000
A88: 87 | B88: ORD00052 | C88: SP000004 | D88: Áo sơ mi thắt eo | E88: Trắng | F88: L | G88: 3 | H88: 250000 | I88: =IF(AND(ISNUMBER(MATCH(C88, Discount_Product_Apply!$B$2:$B$30, 0)), G88>=3), "DIS_004", "") | J88: =IF(I88="DIS_004", INT(G88/3)*500000 + MOD(G88,3)*H88, H88*G88) -> 750000
A89: 88 | B89: ORD00052 | C89: SP000115 | D89: Áo tanktop cotton phối tape form loose | E89: Trắng | F89: S | G89: 1 | H89: 230000 | I89: =IF(AND(ISNUMBER(MATCH(C89, Discount_Product_Apply!$B$2:$B$30, 0)), G89>=3), "DIS_004", "") | J89: =IF(I89="DIS_004", INT(G89/3)*500000 + MOD(G89,3)*H89, H89*G89) -> 230000
A90: 89 | B90: ORD00053 | C90: SP000116 | D90: Áo tanktop cotton phối tape form loose | E90: Trắng | F90: M | G90: 2 | H90: 230000 | I90: =IF(AND(ISNUMBER(MATCH(C90, Discount_Product_Apply!$B$2:$B$30, 0)), G90>=3), "DIS_004", "") | J90: =IF(I90="DIS_004", INT(G90/3)*500000 + MOD(G90,3)*H90, H90*G90) -> 460000
A91: 90 | B91: ORD00053 | C91: SP000117 | D91: Áo tanktop cotton phối tape form loose | E91: Trắng | F91: L | G91: 3 | H91: 230000 | I91: =IF(AND(ISNUMBER(MATCH(C91, Discount_Product_Apply!$B$2:$B$30, 0)), G91>=3), "DIS_004", "") | J91: =IF(I91="DIS_004", INT(G91/3)*500000 + MOD(G91,3)*H91, H91*G91) -> 690000
A92: 91 | B92: ORD00054 | C92: SP000118 | D92: Áo tanktop cotton phối tape form loose | E92: Xám đậm | F92: S | G92: 2 | H92: 230000 | I92: =IF(AND(ISNUMBER(MATCH(C92, Discount_Product_Apply!$B$2:$B$30, 0)), G92>=3), "DIS_004", "") | J92: =IF(I92="DIS_004", INT(G92/3)*500000 + MOD(G92,3)*H92, H92*G92) -> 460000
A93: 92 | B93: ORD00054 | C93: SP000119 | D93: Áo tanktop cotton phối tape form loose | E93: Xám đậm | F93: M | G93: 3 | H93: 230000 | I93: =IF(AND(ISNUMBER(MATCH(C93, Discount_Product_Apply!$B$2:$B$30, 0)), G93>=3), "DIS_004", "") | J93: =IF(I93="DIS_004", INT(G93/3)*500000 + MOD(G93,3)*H93, H93*G93) -> 690000
A94: 93 | B94: ORD00055 | C94: SP000120 | D94: Áo tanktop cotton phối tape form loose | E94: Xám đậm | F94: L | G94: 1 | H94: 230000 | I94: =IF(AND(ISNUMBER(MATCH(C94, Discount_Product_Apply!$B$2:$B$30, 0)), G94>=3), "DIS_004", "") | J94: =IF(I94="DIS_004", INT(G94/3)*500000 + MOD(G94,3)*H94, H94*G94) -> 230000
A95: 94 | B95: ORD00055 | C95: SP000122 | D95: Áo croptop tay ngắn vải linen form regular | E95: Trắng | F95: M | G95: 2 | H95: 230000 | I95: =IF(AND(ISNUMBER(MATCH(C95, Discount_Product_Apply!$B$2:$B$30, 0)), G95>=3), "DIS_004", "") | J95: =IF(I95="DIS_004", INT(G95/3)*500000 + MOD(G95,3)*H95, H95*G95) -> 460000
A96: 95 | B96: ORD00056 | C96: SP000123 | D96: Áo croptop tay ngắn vải linen form regular | E96: Trắng | F96: L | G96: 3 | H96: 230000 | I96: =IF(AND(ISNUMBER(MATCH(C96, Discount_Product_Apply!$B$2:$B$30, 0)), G96>=3), "DIS_004", "") | J96: =IF(I96="DIS_004", INT(G96/3)*500000 + MOD(G96,3)*H96, H96*G96) -> 690000
... A200: 199 | B200: ORD00128 | C200: SP000274 | D200: Quần dài kaki Wide leg | E200: Be | F200: M | G200: 2 | H200: 265000 | I200: =IF(AND(ISNUMBER(MATCH(C200, Discount_Product_Apply!$B$2:$B$30, 0)), G200>=3), "DIS_004", "") | J200: =IF(I200="DIS_004", INT(G200/3)*500000 + MOD(G200,3)*H200, H200*G200) -> 530000
A201: 200 | B201: ORD00129 | C201: SP000221 | D201: Quần short denim | E201: Đen | F201: XL | G201: 200 | H201: 150000 | J201: =IF(I201="DIS_004", INT(G201/3)*500000 + MOD(G201,3)*H201, H201*G201) -> 30000000
A202: 201 | B202: ORD00129 | C202: SP000298 | D202: Chân váy denim nữ A line | E202: Xanh nhạt | F202: S | G202: 200 | H202: 335000 | J202: =IF(I202="DIS_004", INT(G202/3)*500000 + MOD(G202,3)*H202, H202*G202) -> 67000000
A203: 202 | B203: ORD00130 | C203: SP000142 | D203: Áo khoác bomber Regular | E203: Đen | F203: XL | G203: 150 | H203: 380000 | J203: =IF(I203="DIS_004", INT(G203/3)*500000 + MOD(G203,3)*H203, H203*G203) -> 57000000
A204: 203 | B204: ORD00130 | C204: SP000154 | D204: Áo khoác thể thao chống tia UV bo chun loose | E204: Trắng | F204: S | G204: 200 | H204: 380000 | J204: =IF(I204="DIS_004", INT(G204/3)*500000 + MOD(G204,3)*H204, H204*G204) -> 76000000
A205: 204 | B205: ORD00131 | C205: SP000126 | D205: Áo croptop tay ngắn vải linen form regular | E205: Vàng nhạt | F205: L | G205: 200 | H205: 230000 | J205: =IF(I205="DIS_004", INT(G205/3)*500000 + MOD(G205,3)*H205, H205*G205) -> 46000000
A206: 205 | B206: ORD00131 | C206: SP000127 | D206: Áo hai dây bản to cotton form regular | E206: Đen | F206: S | G206: 170 | H206: 230000 | J206: =IF(I206="DIS_004", INT(G206/3)*500000 + MOD(G206,3)*H206, H206*G206) -> 39100000

Sheet Discount
A1: Discount_ID | B1: Discount_Type | C1: Description | D1: StartDate | E1: EndDate | F1: MinQuantity | G1: MinTotal | H1: ComboQuantity | I1: DiscountValue | J1: IsActive
A2: DIS_001 | B2: PERCENT | C2: Giảm 10% cho đơn từ 500K | D2: 45870 | E2: 45900 | F2: NULL | G2: 500000 | H2: NULL | I2: 10 | J2: 0
A3: DIS_002 | B3: AMOUNT | C3: Giảm ngay 50K cho đơn từ 700K | D3: 45901 | E3: 45930 | F3: NULL | G3: 700000 | H3: NULL | I3: 50000 | J3: 0
A4: DIS_003 | B4: PERCENT | C4: Giảm 20% cho đơn trên 1 triệu | D4: 07/07/2025 15/07/2025 | E4: 07/07/2025 15/07/2025 | F4: NULL | G4: 1000000 | H4: NULL | I4: 20 | J4: 0
A5: DIS_004 | B5: COMBO | C5: Combo 3 áo chỉ 500.000 | D5: 45839 | E5: 45849 | F5: 3 | G5: NULL | H5: 3 | I5: 500000 | J5: 0

Sheet Discount_Product_Apply
A1: Discount_ID | B1: Product_ID
A2: DIS_004 | B2: SP000025
A3: DIS_004 | B3: SP000026
A4: DIS_004 | B4: SP000027
A5: DIS_004 | B5: SP000028
A6: DIS_004 | B6: SP000029
A7: DIS_004 | B7: SP000030
A8: DIS_004 | B8: SP000031
A9: DIS_004 | B9: SP000032
A10: DIS_004 | B10: SP000033
A11: DIS_004 | B11: SP000050
A12: DIS_004 | B12: SP000051
... A30: DIS_004 | B30: SP000084

Sheet Import
A1: Import_ID | B1: Partner_ID | C1: Emp_ID | D1: Import_Date | E1: Total
A2: IP0001 | B2: P0061 | C2: EMP0001 | D2: 45828 | E2: =IF(B2="P0061", SUMPRODUCT(Product!$G$2:$G$15, Product!$H$2:$H$15), IF(B2="P0062", SUMPRODUCT(Product!$G$16:$G$50, Product!$H$16:$H$50), IF(B2="P0063", SUMPRODUCT(Product!$G$51:$G$65, Product!$H$51:$H$65), IF(B2="P0064", SUMPRODUCT(Product!$G$66:$G$85, Product!$H$66:$H$85), IF(B2="P0065", SUMPRODUCT(Product!$G$86:$G$115, Product!$H$86:$H$115), IF(B2="P0066", SUMPRODUCT(Product!$G$116:$G$139, Product!$H$116:$H$139), IF(B2="P0067", SUMPRODUCT(Product!$G$140:$G$169, Product!$H$140:$H$169), IF(B2="P0068", SUMPRODUCT(Product!$G$170:$G$189, Product!$H$170:$H$189), IF(B2="P0069", SUMPRODUCT(Product!$G$190:$G$209, Product!$H$190:$H$209), IF(B2="P0070", SUMPRODUCT(Product!$G$210:$G$233, Product!$H$210:$H$233), IF(B2="P0071", SUMPRODUCT(Product!$G$234:$G$273, Product!$H$234:$H$273), IF(B2="P0072", SUMPRODUCT(Product!$G$274:$G$304, Product!$H$274:$H$304), 0)))))))))))) -> 640980000
A3: IP0002 | B3: P0062 | C3: EMP0001 | D3: 45828 | E3: =IF(B3="P0061", SUMPRODUCT(Product!$G$2:$G$15, Product!$H$2:$H$15), IF(B3="P0062", SUMPRODUCT(Product!$G$16:$G$50, Product!$H$16:$H$50), IF(B3="P0063", SUMPRODUCT(Product!$G$51:$G$65, Product!$H$51:$H$65), IF(B3="P0064", SUMPRODUCT(Product!$G$66:$G$85, Product!$H$66:$H$85), IF(B3="P0065", SUMPRODUCT(Product!$G$86:$G$115, Product!$H$86:$H$115), IF(B3="P0066", SUMPRODUCT(Product!$G$116:$G$139, Product!$H$116:$H$139), IF(B3="P0067", SUMPRODUCT(Product!$G$140:$G$169, Product!$H$140:$H$169), IF(B3="P0068", SUMPRODUCT(Product!$G$170:$G$189, Product!$H$170:$H$189), IF(B3="P0069", SUMPRODUCT(Product!$G$190:$G$209, Product!$H$190:$H$209), IF(B3="P0070", SUMPRODUCT(Product!$G$210:$G$233, Product!$H$210:$H$233), IF(B3="P0071", SUMPRODUCT(Product!$G$234:$G$273, Product!$H$234:$H$273), IF(B3="P0072", SUMPRODUCT(Product!$G$274:$G$304, Product!$H$274:$H$304), 0)))))))))))) -> 1788930000
A4: IP0003 | B4: P0063 | C4: EMP0001 | D4: 45828 | E4: =IF(B4="P0061", SUMPRODUCT(Product!$G$2:$G$15, Product!$H$2:$H$15), IF(B4="P0062", SUMPRODUCT(Product!$G$16:$G$50, Product!$H$16:$H$50), IF(B4="P0063", SUMPRODUCT(Product!$G$51:$G$65, Product!$H$51:$H$65), IF(B4="P0064", SUMPRODUCT(Product!$G$66:$G$85, Product!$H$66:$H$85), IF(B4="P0065", SUMPRODUCT(Product!$G$86:$G$115, Product!$H$86:$H$115), IF(B4="P0066", SUMPRODUCT(Product!$G$116:$G$139, Product!$H$116:$H$139), IF(B4="P0067", SUMPRODUCT(Product!$G$140:$G$169, Product!$H$140:$H$169), IF(B4="P0068", SUMPRODUCT(Product!$G$170:$G$189, Product!$H$170:$H$189), IF(B4="P0069", SUMPRODUCT(Product!$G$190:$G$209, Product!$H$190:$H$209), IF(B4="P0070", SUMPRODUCT(Product!$G$210:$G$233, Product!$H$210:$H$233), IF(B4="P0071", SUMPRODUCT(Product!$G$234:$G$273, Product!$H$234:$H$273), IF(B4="P0072", SUMPRODUCT(Product!$G$274:$G$304, Product!$H$274:$H$304), 0)))))))))))) -> 769920000
A5: IP0004 | B5: P0064 | C5: EMP0002 | D5: 45829 | E5: =IF(B5="P0061", SUMPRODUCT(Product!$G$2:$G$15, Product!$H$2:$H$15), IF(B5="P0062", SUMPRODUCT(Product!$G$16:$G$50, Product!$H$16:$H$50), IF(B5="P0063", SUMPRODUCT(Product!$G$51:$G$65, Product!$H$51:$H$65), IF(B5="P0064", SUMPRODUCT(Product!$G$66:$G$85, Product!$H$66:$H$85), IF(B5="P0065", SUMPRODUCT(Product!$G$86:$G$115, Product!$H$86:$H$115), IF(B5="P0066", SUMPRODUCT(Product!$G$116:$G$139, Product!$H$116:$H$139), IF(B5="P0067", SUMPRODUCT(Product!$G$140:$G$169, Product!$H$140:$H$169), IF(B5="P0068", SUMPRODUCT(Product!$G$170:$G$189, Product!$H$170:$H$189), IF(B5="P0069", SUMPRODUCT(Product!$G$190:$G$209, Product!$H$190:$H$209), IF(B5="P0070", SUMPRODUCT(Product!$G$210:$G$233, Product!$H$210:$H$233), IF(B5="P0071", SUMPRODUCT(Product!$G$234:$G$273, Product!$H$234:$H$273), IF(B5="P0072", SUMPRODUCT(Product!$G$274:$G$304, Product!$H$274:$H$304), 0)))))))))))) -> 1177930000
A6: IP0005 | B6: P0065 | C6: EMP0002 | D6: 45829 | E6: =IF(B6="P0061", SUMPRODUCT(Product!$G$2:$G$15, Product!$H$2:$H$15), IF(B6="P0062", SUMPRODUCT(Product!$G$16:$G$50, Product!$H$16:$H$50), IF(B6="P0063", SUMPRODUCT(Product!$G$51:$G$65, Product!$H$51:$H$65), IF(B6="P0064", SUMPRODUCT(Product!$G$66:$G$85, Product!$H$66:$H$85), IF(B6="P0065", SUMPRODUCT(Product!$G$86:$G$115, Product!$H$86:$H$115), IF(B6="P0066", SUMPRODUCT(Product!$G$116:$G$139, Product!$H$116:$H$139), IF(B6="P0067", SUMPRODUCT(Product!$G$140:$G$169, Product!$H$140:$H$169), IF(B6="P0068", SUMPRODUCT(Product!$G$170:$G$189, Product!$H$170:$H$189), IF(B6="P0069", SUMPRODUCT(Product!$G$190:$G$209, Product!$H$190:$H$209), IF(B6="P0070", SUMPRODUCT(Product!$G$210:$G$233, Product!$H$210:$H$233), IF(B6="P0071", SUMPRODUCT(Product!$G$234:$G$273, Product!$H$234:$H$273), IF(B6="P0072", SUMPRODUCT(Product!$G$274:$G$304, Product!$H$274:$H$304), 0)))))))))))) -> 1724626000
A7: IP0006 | B7: P0066 | C7: EMP0002 | D7: 45829 | E7: =IF(B7="P0061",SUMPRODUCT(Product!$G$2:$G$15,Product!$H$2:$H$15), IF(B7="P0062",SUMPRODUCT(Product!$G$16:$G$50,Product!$H$16:$H$50), IF(B7="P0063",SUMPRODUCT(Product!$G$51:$G$65,Product!$H$51:$H$65), IF(B7="P0064",SUMPRODUCT(Product!$G$66:$G$85,Product!$H$66:$H$85), IF(B7="P0065",SUMPRODUCT(Product!$G$86:$G$115,Product!$H$86:$H$115), IF(B7="P0066",SUMPRODUCT(Product!$G$116:$G$139,Product!$H$116:$H$139), IF(B7="P0067",SUMPRODUCT(Product!$G$140:$G$169,Product!$H$140:$H$169), IF(B7="P0068",SUMPRODUCT(Product!$G$170:$G$189,Product!$H$170:$H$189), IF(B7="P0069",SUMPRODUCT(Product!$G$190:$G$209,Product!$H$190:$H$209), IF(B7="P0070",SUMPRODUCT(Product!$G$210:$G$233,Product!$H$210:$H$233), IF(B7="P0071",SUMPRODUCT(Product!$G$234:$G$273,Product!$H$234:$H$273), IF(B7="P0072",SUMPRODUCT(Product!$G$274:$G$304,Product!$H$274:$H$304), 0))))))))))))-(155000*7058) -> 775000000
A8: IP0007 | B8: P0067 | C8: EMP0002 | D8: 45829 | E8: =IF(B8="P0061", SUMPRODUCT(Product!$G$2:$G$15, Product!$H$2:$H$15), IF(B8="P0062", SUMPRODUCT(Product!$G$16:$G$50, Product!$H$16:$H$50), IF(B8="P0063", SUMPRODUCT(Product!$G$51:$G$65, Product!$H$51:$H$65), IF(B8="P0064", SUMPRODUCT(Product!$G$66:$G$85, Product!$H$66:$H$85), IF(B8="P0065", SUMPRODUCT(Product!$G$86:$G$115, Product!$H$86:$H$115), IF(B8="P0066", SUMPRODUCT(Product!$G$116:$G$139, Product!$H$116:$H$139), IF(B8="P0067", SUMPRODUCT(Product!$G$140:$G$169, Product!$H$140:$H$169), IF(B8="P0068", SUMPRODUCT(Product!$G$170:$G$189, Product!$H$170:$H$189), IF(B8="P0069", SUMPRODUCT(Product!$G$190:$G$209, Product!$H$190:$H$209), IF(B8="P0070", SUMPRODUCT(Product!$G$210:$G$233, Product!$H$210:$H$233), IF(B8="P0071", SUMPRODUCT(Product!$G$234:$G$273, Product!$H$234:$H$273), IF(B8="P0072", SUMPRODUCT(Product!$G$274:$G$304, Product!$H$274:$H$304), 0))))))))))))-(250000*3288+250000*2372+110000*2070) -> 1330000000
A9: IP0008 | B9: P0068 | C9: EMP0003 | D9: 45830 | E9: =IF(B9="P0061", SUMPRODUCT(Product!$G$2:$G$15, Product!$H$2:$H$15), IF(B9="P0062", SUMPRODUCT(Product!$G$16:$G$50, Product!$H$16:$H$50), IF(B9="P0063", SUMPRODUCT(Product!$G$51:$G$65, Product!$H$51:$H$65), IF(B9="P0064", SUMPRODUCT(Product!$G$66:$G$85, Product!$H$66:$H$85), IF(B9="P0065", SUMPRODUCT(Product!$G$86:$G$115, Product!$H$86:$H$115), IF(B9="P0066", SUMPRODUCT(Product!$G$116:$G$139, Product!$H$116:$H$139), IF(B9="P0067", SUMPRODUCT(Product!$G$140:$G$169, Product!$H$140:$H$169), IF(B9="P0068", SUMPRODUCT(Product!$G$170:$G$189, Product!$H$170:$H$189), IF(B9="P0069", SUMPRODUCT(Product!$G$190:$G$209, Product!$H$190:$H$209), IF(B9="P0070", SUMPRODUCT(Product!$G$210:$G$233, Product!$H$210:$H$233), IF(B9="P0071", SUMPRODUCT(Product!$G$234:$G$273, Product!$H$234:$H$273), IF(B9="P0072", SUMPRODUCT(Product!$G$274:$G$304, Product!$H$274:$H$304), 0)))))))))))) -> 1152100000
A10: IP0009 | B10: P0069 | C10: EMP0003 | D10: 45830 | E10: =IF(B10="P0061", SUMPRODUCT(Product!$G$2:$G$15, Product!$H$2:$H$15), IF(B10="P0062", SUMPRODUCT(Product!$G$16:$G$50, Product!$H$16:$H$50), IF(B10="P0063", SUMPRODUCT(Product!$G$51:$G$65, Product!$H$51:$H$65), IF(B10="P0064", SUMPRODUCT(Product!$G$66:$G$85, Product!$H$66:$H$85), IF(B10="P0065", SUMPRODUCT(Product!$G$86:$G$115, Product!$H$86:$H$115), IF(B10="P0066", SUMPRODUCT(Product!$G$116:$G$139, Product!$H$116:$H$139), IF(B10="P0067", SUMPRODUCT(Product!$G$140:$G$169, Product!$H$140:$H$169), IF(B10="P0068", SUMPRODUCT(Product!$G$170:$G$189, Product!$H$170:$H$189), IF(B10="P0069", SUMPRODUCT(Product!$G$190:$G$209, Product!$H$190:$H$209), IF(B10="P0070", SUMPRODUCT(Product!$G$210:$G$233, Product!$H$210:$H$233), IF(B10="P0071", SUMPRODUCT(Product!$G$234:$G$273, Product!$H$234:$H$273), IF(B10="P0072", SUMPRODUCT(Product!$G$274:$G$304, Product!$H$274:$H$304), 0)))))))))))) -> 1483920000
A11: IP0010 | B11: P0070 | C11: EMP0003 | D11: 45830 | E11: =IF(B11="P0061", SUMPRODUCT(Product!$G$2:$G$15, Product!$H$2:$H$15), IF(B11="P0062", SUMPRODUCT(Product!$G$16:$G$50, Product!$H$16:$H$50), IF(B11="P0063", SUMPRODUCT(Product!$G$51:$G$65, Product!$H$51:$H$65), IF(B11="P0064", SUMPRODUCT(Product!$G$66:$G$85, Product!$H$66:$H$85), IF(B11="P0065", SUMPRODUCT(Product!$G$86:$G$115, Product!$H$86:$H$115), IF(B11="P0066", SUMPRODUCT(Product!$G$116:$G$139, Product!$H$116:$H$139), IF(B11="P0067", SUMPRODUCT(Product!$G$140:$G$169, Product!$H$140:$H$169), IF(B11="P0068", SUMPRODUCT(Product!$G$170:$G$189, Product!$H$170:$H$189), IF(B11="P0069", SUMPRODUCT(Product!$G$190:$G$209, Product!$H$190:$H$209), IF(B11="P0070", SUMPRODUCT(Product!$G$210:$G$233, Product!$H$210:$H$233), IF(B11="P0071", SUMPRODUCT(Product!$G$234:$G$273, Product!$H$234:$H$273), IF(B11="P0072", SUMPRODUCT(Product!$G$274:$G$304, Product!$H$274:$H$304), 0)))))))))))) -> 1350605000
A12: IP0011 | B12: P0071 | C12: EMP0001 | D12: 45830 | E12: =IF(B12="P0061", SUMPRODUCT(Product!$G$2:$G$15, Product!$H$2:$H$15), IF(B12="P0062", SUMPRODUCT(Product!$G$16:$G$50, Product!$H$16:$H$50), IF(B12="P0063", SUMPRODUCT(Product!$G$51:$G$65, Product!$H$51:$H$65), IF(B12="P0064", SUMPRODUCT(Product!$G$66:$G$85, Product!$H$66:$H$85), IF(B12="P0065", SUMPRODUCT(Product!$G$86:$G$115, Product!$H$86:$H$115), IF(B12="P0066", SUMPRODUCT(Product!$G$116:$G$139, Product!$H$116:$H$139), IF(B12="P0067", SUMPRODUCT(Product!$G$140:$G$169, Product!$H$140:$H$169), IF(B12="P0068", SUMPRODUCT(Product!$G$170:$G$189, Product!$H$170:$H$189), IF(B12="P0069", SUMPRODUCT(Product!$G$190:$G$209, Product!$H$190:$H$209), IF(B12="P0070", SUMPRODUCT(Product!$G$210:$G$233, Product!$H$210:$H$233), IF(B12="P0071", SUMPRODUCT(Product!$G$234:$G$273, Product!$H$234:$H$273), IF(B12="P0072", SUMPRODUCT(Product!$G$274:$G$304, Product!$H$274:$H$304), 0)))))))))))) -> 1764400000
A13: IP0012 | B13: P0072 | C13: EMP0002 | D13: 45834 | E13: =IF(B13="P0061", SUMPRODUCT(Product!$G$2:$G$15, Product!$H$2:$H$15), IF(B13="P0062", SUMPRODUCT(Product!$G$16:$G$50, Product!$H$16:$H$50), IF(B13="P0063", SUMPRODUCT(Product!$G$51:$G$65, Product!$H$51:$H$65), IF(B13="P0064", SUMPRODUCT(Product!$G$66:$G$85, Product!$H$66:$H$85), IF(B13="P0065", SUMPRODUCT(Product!$G$86:$G$115, Product!$H$86:$H$115), IF(B13="P0066", SUMPRODUCT(Product!$G$116:$G$139, Product!$H$116:$H$139), IF(B13="P0067", SUMPRODUCT(Product!$G$140:$G$169, Product!$H$140:$H$169), IF(B13="P0068", SUMPRODUCT(Product!$G$170:$G$189, Product!$H$170:$H$189), IF(B13="P0069", SUMPRODUCT(Product!$G$190:$G$209, Product!$H$190:$H$209), IF(B13="P0070", SUMPRODUCT(Product!$G$210:$G$233, Product!$H$210:$H$233), IF(B13="P0071", SUMPRODUCT(Product!$G$234:$G$273, Product!$H$234:$H$273), IF(B13="P0072", SUMPRODUCT(Product!$G$274:$G$305, Product!$H$274:$H$305), 0))))))))))))-(2424*210000+1635*260000+1285*220000+1439*291000+500*180000) -> 1451000000
A14: IP0013 | B14: P0067 | C14: EMP0001 | D14: 45841 | E14: =IF(B14="P0061", SUMPRODUCT(Product!$G$2:$G$15, Product!$H$2:$H$15), IF(B14="P0062", SUMPRODUCT(Product!$G$16:$G$50, Product!$H$16:$H$50), IF(B14="P0063", SUMPRODUCT(Product!$G$51:$G$65, Product!$H$51:$H$65), IF(B14="P0064", SUMPRODUCT(Product!$G$66:$G$85, Product!$H$66:$H$85), IF(B14="P0065", SUMPRODUCT(Product!$G$86:$G$115, Product!$H$86:$H$115), IF(B14="P0066", SUMPRODUCT(Product!$G$116:$G$139, Product!$H$116:$H$139), IF(B14="P0067", SUMPRODUCT(Product!$G$140:$G$169, Product!$H$140:$H$169), IF(B14="P0068", SUMPRODUCT(Product!$G$170:$G$189, Product!$H$170:$H$189), IF(B14="P0069", SUMPRODUCT(Product!$G$190:$G$209, Product!$H$190:$H$209), IF(B14="P0070", SUMPRODUCT(Product!$G$210:$G$233, Product!$H$210:$H$233), IF(B14="P0071", SUMPRODUCT(Product!$G$234:$G$273, Product!$H$234:$H$273), IF(B14="P0072", SUMPRODUCT(Product!$G$274:$G$304, Product!$H$274:$H$304), 0))))))))))))-(250000*1000+250000*3000+110000*3000) -> 1642700000
A15: IP0014 | B15: P0072 | C15: EMP0003 | D15: 45841 | E15: =IF(B15="P0061", SUMPRODUCT(Product!$G$2:$G$15, Product!$H$2:$H$15), IF(B15="P0062", SUMPRODUCT(Product!$G$16:$G$50, Product!$H$16:$H$50), IF(B15="P0063", SUMPRODUCT(Product!$G$51:$G$65, Product!$H$51:$H$65), IF(B15="P0064", SUMPRODUCT(Product!$G$66:$G$85, Product!$H$66:$H$85), IF(B15="P0065", SUMPRODUCT(Product!$G$86:$G$115, Product!$H$86:$H$115), IF(B15="P0066", SUMPRODUCT(Product!$G$116:$G$139, Product!$H$116:$H$139), IF(B15="P0067", SUMPRODUCT(Product!$G$140:$G$169, Product!$H$140:$H$169), IF(B15="P0068", SUMPRODUCT(Product!$G$170:$G$189, Product!$H$170:$H$189), IF(B15="P0069", SUMPRODUCT(Product!$G$190:$G$209, Product!$H$190:$H$209), IF(B15="P0070", SUMPRODUCT(Product!$G$210:$G$233, Product!$H$210:$H$233), IF(B15="P0071", SUMPRODUCT(Product!$G$234:$G$273, Product!$H$234:$H$273), IF(B15="P0072", SUMPRODUCT(Product!$G$274:$G$305, Product!$H$274:$H$305), 0))))))))))))-(2000*210000+2000*260000+1000*220000+1000*291000) -> 1725589000
A16: IP0015 | B16: P0066 | C16: EMP0003 | D16: 45841 | E16: =IF(B16="P0061",SUMPRODUCT(Product!$G$2:$G$15,Product!$H$2:$H$15), IF(B16="P0062",SUMPRODUCT(Product!$G$16:$G$50,Product!$H$16:$H$50), IF(B16="P0063",SUMPRODUCT(Product!$G$51:$G$65,Product!$H$51:$H$65), IF(B16="P0064",SUMPRODUCT(Product!$G$66:$G$85,Product!$H$66:$H$85), IF(B16="P0065",SUMPRODUCT(Product!$G$86:$G$115,Product!$H$86:$H$115), IF(B16="P0066",SUMPRODUCT(Product!$G$116:$G$139,Product!$H$116:$H$139), IF(B16="P0067",SUMPRODUCT(Product!$G$140:$G$169,Product!$H$140:$H$169), IF(B16="P0068",SUMPRODUCT(Product!$G$170:$G$189,Product!$H$170:$H$189), IF(B16="P0069",SUMPRODUCT(Product!$G$190:$G$209,Product!$H$190:$H$209), IF(B16="P0070",SUMPRODUCT(Product!$G$210:$G$233,Product!$H$210:$H$233), IF(B16="P0071",SUMPRODUCT(Product!$G$234:$G$273,Product!$H$234:$H$273), IF(B16="P0072",SUMPRODUCT(Product!$G$274:$G$304,Product!$H$274:$H$304), 0))))))))))))-(155000*5000) -> 1093990000

Sheet Import_Detail
A1: ImportDetail_ID | B1: Import_ID | C1: Product_ID | D1: Product_Name | E1: Color | F1: Size | G1: Quantity | H1: Price
A2: 1 | B2: IP0001 | C2: SP000001 | D2: Áo sơ mi thắt eo | E2: Trắng | F2: XS | G2: 324 | H2: 120000
A3: 2 | B3: IP0001 | C3: SP000002 | D3: Áo sơ mi thắt eo | E3: Trắng | F3: S | G3: 549 | H3: 120000
A4: 3 | B4: IP0001 | C4: SP000003 | D4: Áo sơ mi thắt eo | E4: Trắng | F4: M | G4: 372 | H4: 120000
A5: 4 | B5: IP0001 | C5: SP000004 | D5: Áo sơ mi thắt eo | E5: Trắng | F5: L | G5: 606 | H5: 120000
A6: 5 | B6: IP0001 | C6: SP000005 | D6: Áo sơ mi cộc tay poly rayon xám form regular | E6: Xám | F6: S | G6: 394 | H6: 90000
A7: 6 | B7: IP0001 | C7: SP000006 | D7: Áo sơ mi cộc tay poly rayon xám form regular | E7: Xám | F7: M | G7: 347 | H7: 90000
A8: 7 | B8: IP0001 | C8: SP000007 | D8: Áo sơ mi cộc tay poly rayon xám form regular | E8: Xám | F8: L | G8: 564 | H8: 90000
A9: 8 | B9: IP0001 | C9: SP000008 | D9: Áo sơ mi cộc tay poly rayon xám form regular | E9: Xám | F9: XL | G9: 713 | H9: 90000
A10: 9 | B10: IP0001 | C10: SP000009 | D10: Áo sơ mi cộc tay poly rayon xám form regular | E10: Xám | F10: XXL | G10: 340 | H10: 90000
A11: 10 | B11: IP0001 | C11: SP000010 | D11: Áo sơ mi cộc tay poly rayon xám form regular | E11: Xanh than | F11: S | G11: 59 | H11: 90000
A12: 11 | B12: IP0001 | C12: SP000011 | D12: Áo sơ mi cộc tay poly rayon xám form regular | E12: Xanh than | F12: M | G12: 698 | H12: 90000
A13: 12 | B13: IP0001 | C13: SP000012 | D13: Áo sơ mi cộc tay poly rayon xám form regular | E13: Xanh than | F13: L | G13: 527 | H13: 90000
... A275: 274 | B275: IP0012 | C275: SP000274 | D275: Quần dài kaki Wide leg | E275: Be | F275: M | G275: 255 | H275: 210000
A276: 275 | B276: IP0012 | C276: SP000275 | D276: Quần dài kaki Wide leg | E276: Be | F276: L | G276: =203-65 -> 138 | H276: 210000
A277: 276 | B277: IP0012 | C277: SP000276 | D277: Quần dài kaki Wide leg | E277: Be | F277: XL | G277: 207 | H277: 210000
A278: 277 | B278: IP0012 | C278: SP000277 | D278: Quần dài kaki Wide leg | E278: Be | F278: XXL | G278: 189 | H278: 210000
A279: 278 | B279: IP0012 | C279: SP000278 | D279: Quần dài kaki Wide leg | E279: Rêu | F279: S | G279: 117 | H279: 210000
A280: 279 | B280: IP0012 | C280: SP000279 | D280: Quần dài kaki Wide leg | E280: Rêu | F280: M | G280: 255 | H280: 210000
A281: 280 | B281: IP0012 | C281: SP000280 | D281: Quần dài kaki Wide leg | E281: Rêu | F281: L | G281: 116 | H281: 210000
A282: 281 | B282: IP0012 | C282: SP000281 | D282: Quần dài kaki Wide leg | E282: Rêu | F282: XL | G282: 250 | H282: 210000
A283: 282 | B283: IP0012 | C283: SP000282 | D283: Quần dài kaki Wide leg | E283: Rêu | F283: XXL | G283: 257 | H283: 210000
A284: 283 | B284: IP0012 | C284: SP000283 | D284: Chân váy chữ A công sở | E284: Đen | F284: S | G284: 129 | H284: 260000
A285: 284 | B285: IP0012 | C285: SP000284 | D285: Chân váy chữ A công sở | E285: Đen | F285: M | G285: 188 | H285: 260000
A286: 285 | B286: IP0012 | C286: SP000285 | D286: Chân váy chữ A công sở | E286: Đen | F286: L | G286: 206 | H286: 260000
A287: 286 | B287: IP0012 | C287: SP000286 | D287: Chân váy chữ A công sở | E287: Đen | F287: XL | G287: 278 | H287: 260000
A288: 287 | B288: IP0012 | C288: SP000287 | D288: Chân váy chữ A công sở | E288: Đen | F288: XXL | G288: 213 | H288: 260000
... A304: 303 | B304: IP0012 | C304: SP000303 | D304: Chân váy denim nữ A line | E304: Xanh đậm | F304: L | G304: 123 | H304: 291000
A305: 304 | B305: IP0013 | C305: SP000139 | D305: Áo khoác bomber Regular | E305: Đen | F305: S | H305: 250000
A306: 305 | B306: IP0013 | C306: SP000140 | D306: Áo khoác bomber Regular | E306: Đen | F306: M | H306: 250000
A307: 306 | B307: IP0013 | C307: SP000141 | D307: Áo khoác bomber Regular | E307: Đen | F307: L | H307: 250000
A308: 307 | B308: IP0013 | C308: SP000142 | D308: Áo khoác bomber Regular | E308: Đen | F308: XL | G308: =Product!G143-Import_Detail!G143 -> 301 | H308: 250000
A309: 308 | B309: IP0013 | C309: SP000143 | D309: Áo khoác bomber Regular | E309: Đen | F309: XXL | G309: =Product!G144-Import_Detail!G144 -> 78 | H309: 250000
A310: 309 | B310: IP0013 | C310: SP000144 | D310: Áo khoác bomber Regular | E310: Rêu | F310: S | G310: =Product!G145-Import_Detail!G145 -> 298 | H310: 250000
A311: 310 | B311: IP0013 | C311: SP000145 | D311: Áo khoác bomber Regular | E311: Rêu | F311: M | G311: =Product!G146-Import_Detail!G146 -> 297 | H311: 250000
A312: 311 | B312: IP0013 | C312: SP000146 | D312: Áo khoác bomber Regular | E312: Rêu | F312: L | G312: =Product!G147-Import_Detail!G147 -> 117 | H312: 250000
A313: 312 | B313: IP0013 | C313: SP000147 | D313: Áo khoác bomber Regular | E313: Rêu | F313: XL | G313: =Product!G148-Import_Detail!G148 -> 211 | H313: 250000
